[2023-12-12T18:34:45.527+0000] {taskinstance.py:1159} INFO - Dependencies all met for dep_context=non-requeueable deps ti=<TaskInstance: crawl_and_store_to_mysql_02.store_csv_to_mysql manual__2023-12-12T18:34:38.984579+00:00 [queued]>
[2023-12-12T18:34:45.534+0000] {taskinstance.py:1159} INFO - Dependencies all met for dep_context=requeueable deps ti=<TaskInstance: crawl_and_store_to_mysql_02.store_csv_to_mysql manual__2023-12-12T18:34:38.984579+00:00 [queued]>
[2023-12-12T18:34:45.535+0000] {taskinstance.py:1361} INFO - Starting attempt 1 of 2
[2023-12-12T18:34:45.545+0000] {taskinstance.py:1382} INFO - Executing <Task(PythonOperator): store_csv_to_mysql> on 2023-12-12 18:34:38.984579+00:00
[2023-12-12T18:34:45.552+0000] {standard_task_runner.py:57} INFO - Started process 217 to run task
[2023-12-12T18:34:45.555+0000] {standard_task_runner.py:84} INFO - Running: ['***', 'tasks', 'run', 'crawl_and_store_to_mysql_02', 'store_csv_to_mysql', 'manual__2023-12-12T18:34:38.984579+00:00', '--job-id', '152', '--raw', '--subdir', 'DAGS_FOLDER/download_cctv_data_02.py', '--cfg-path', '/tmp/tmpcawzcrr3']
[2023-12-12T18:34:45.558+0000] {standard_task_runner.py:85} INFO - Job 152: Subtask store_csv_to_mysql
[2023-12-12T18:34:45.599+0000] {task_command.py:416} INFO - Running <TaskInstance: crawl_and_store_to_mysql_02.store_csv_to_mysql manual__2023-12-12T18:34:38.984579+00:00 [running]> on host 870c4047aa24
[2023-12-12T18:34:45.659+0000] {taskinstance.py:1662} INFO - Exporting env vars: AIRFLOW_CTX_DAG_OWNER='xin' AIRFLOW_CTX_DAG_ID='crawl_and_store_to_mysql_02' AIRFLOW_CTX_TASK_ID='store_csv_to_mysql' AIRFLOW_CTX_EXECUTION_DATE='2023-12-12T18:34:38.984579+00:00' AIRFLOW_CTX_TRY_NUMBER='1' AIRFLOW_CTX_DAG_RUN_ID='manual__2023-12-12T18:34:38.984579+00:00'
[2023-12-12T18:34:45.663+0000] {taskinstance.py:1937} ERROR - Task failed with exception
Traceback (most recent call last):
  File "/home/airflow/.local/lib/python3.8/site-packages/pymysql/connections.py", line 644, in connect
    sock = socket.create_connection(
  File "/usr/local/lib/python3.8/socket.py", line 808, in create_connection
    raise err
  File "/usr/local/lib/python3.8/socket.py", line 796, in create_connection
    sock.connect(sa)
OSError: [Errno 99] Cannot assign requested address

During handling of the above exception, another exception occurred:

Traceback (most recent call last):
  File "/home/airflow/.local/lib/python3.8/site-packages/airflow/operators/python.py", line 192, in execute
    return_value = self.execute_callable()
  File "/home/airflow/.local/lib/python3.8/site-packages/airflow/operators/python.py", line 209, in execute_callable
    return self.python_callable(*self.op_args, **self.op_kwargs)
  File "/opt/airflow/dags/download_cctv_data_02.py", line 119, in store_csv_to_mysql
    connection = pymysql.connect(
  File "/home/airflow/.local/lib/python3.8/site-packages/pymysql/connections.py", line 358, in __init__
    self.connect()
  File "/home/airflow/.local/lib/python3.8/site-packages/pymysql/connections.py", line 711, in connect
    raise exc
pymysql.err.OperationalError: (2003, "Can't connect to MySQL server on 'localhost' ([Errno 99] Cannot assign requested address)")
[2023-12-12T18:34:45.673+0000] {taskinstance.py:1400} INFO - Marking task as UP_FOR_RETRY. dag_id=crawl_and_store_to_mysql_02, task_id=store_csv_to_mysql, execution_date=20231212T183438, start_date=20231212T183445, end_date=20231212T183445
[2023-12-12T18:34:45.683+0000] {standard_task_runner.py:104} ERROR - Failed to execute job 152 for task store_csv_to_mysql ((2003, "Can't connect to MySQL server on 'localhost' ([Errno 99] Cannot assign requested address)"); 217)
[2023-12-12T18:34:45.727+0000] {local_task_job_runner.py:228} INFO - Task exited with return code 1
[2023-12-12T18:34:45.741+0000] {taskinstance.py:2778} INFO - 0 downstream tasks scheduled from follow-on schedule check
