[2023-12-17T01:53:35.091+0000] {taskinstance.py:1159} INFO - Dependencies all met for dep_context=non-requeueable deps ti=<TaskInstance: datalake_refresh_dataflow_powerbi.taskRefreshDataflowPowerBI manual__2023-12-17T01:53:30.539564+00:00 [queued]>
[2023-12-17T01:53:35.099+0000] {taskinstance.py:1159} INFO - Dependencies all met for dep_context=requeueable deps ti=<TaskInstance: datalake_refresh_dataflow_powerbi.taskRefreshDataflowPowerBI manual__2023-12-17T01:53:30.539564+00:00 [queued]>
[2023-12-17T01:53:35.100+0000] {taskinstance.py:1361} INFO - Starting attempt 1 of 1
[2023-12-17T01:53:35.111+0000] {taskinstance.py:1382} INFO - Executing <Task(PowerBIDataflowRefreshOperator): taskRefreshDataflowPowerBI> on 2023-12-17 01:53:30.539564+00:00
[2023-12-17T01:53:35.117+0000] {standard_task_runner.py:57} INFO - Started process 7443 to run task
[2023-12-17T01:53:35.120+0000] {standard_task_runner.py:84} INFO - Running: ['***', 'tasks', 'run', 'datalake_refresh_dataflow_powerbi', 'taskRefreshDataflowPowerBI', 'manual__2023-12-17T01:53:30.539564+00:00', '--job-id', '158', '--raw', '--subdir', 'DAGS_FOLDER/datalake_refresh_dataflow_powerbi.py', '--cfg-path', '/tmp/tmpfrjk48lq']
[2023-12-17T01:53:35.122+0000] {standard_task_runner.py:85} INFO - Job 158: Subtask taskRefreshDataflowPowerBI
[2023-12-17T01:53:35.162+0000] {task_command.py:416} INFO - Running <TaskInstance: datalake_refresh_dataflow_powerbi.taskRefreshDataflowPowerBI manual__2023-12-17T01:53:30.539564+00:00 [running]> on host 83c86e565932
[2023-12-17T01:53:35.231+0000] {taskinstance.py:1662} INFO - Exporting env vars: AIRFLOW_CTX_DAG_OWNER='xin' AIRFLOW_CTX_DAG_ID='datalake_refresh_dataflow_powerbi' AIRFLOW_CTX_TASK_ID='taskRefreshDataflowPowerBI' AIRFLOW_CTX_EXECUTION_DATE='2023-12-17T01:53:30.539564+00:00' AIRFLOW_CTX_TRY_NUMBER='1' AIRFLOW_CTX_DAG_RUN_ID='manual__2023-12-17T01:53:30.539564+00:00'
[2023-12-17T01:53:35.232+0000] {powerbi_dataflow_refresh_operator.py:88} INFO - Calling API Dataflow ID: fdbac82b-4169-4aaf-80c2-1f6cdde56b46
[2023-12-17T01:53:35.233+0000] {logging_mixin.py:154} INFO - Refresh dataflow url: https://api.powerbi.com/v1.0/myorg/datasets/fdbac82b-4169-4aaf-80c2-1f6cdde56b46/refreshes - headers: {'Content-Type': 'application/json', 'Authorization': 'Bearer eyJ0eXAiOiJKV1QiLCJhbGciOiJSUzI1NiIsIng1dCI6IlQxU3QtZExUdnlXUmd4Ql82NzZ1OGtyWFMtSSIsImtpZCI6IlQxU3QtZExUdnlXUmd4Ql82NzZ1OGtyWFMtSSJ9.eyJhdWQiOiJodHRwczovL2FuYWx5c2lzLndpbmRvd3MubmV0L3Bvd2VyYmkvYXBpIiwiaXNzIjoiaHR0cHM6Ly9zdHMud2luZG93cy5uZXQvZDIxYjc0NzQtMWU3ZC00MGJhLTk1ZjItNGQ0NWJjZTc2YTJiLyIsImlhdCI6MTcwMjc3NzcxMywibmJmIjoxNzAyNzc3NzEzLCJleHAiOjE3MDI3ODE2MTMsImFpbyI6IkUyVmdZT2hqV0JKNU9qN1M5SGxMZktkalR1cFJBQT09IiwiYXBwaWQiOiJiZWM0MWFiOC1lMzNhLTRiODMtOTJkNi05ZDJjOTU3Zjk0NGMiLCJhcHBpZGFjciI6IjEiLCJpZHAiOiJodHRwczovL3N0cy53aW5kb3dzLm5ldC9kMjFiNzQ3NC0xZTdkLTQwYmEtOTVmMi00ZDQ1YmNlNzZhMmIvIiwiaWR0eXAiOiJhcHAiLCJvaWQiOiJlY2FlZTAyOS00OTczLTQ4MjQtOWU4MS04NDA1Y2RjOGIzMDMiLCJyaCI6IjAuQVhJQWRIUWIwbjBldWtDVjhrMUZ2T2RxS3drQUFBQUFBQUFBd0FBQUFBQUFBQUREQUFBLiIsInN1YiI6ImVjYWVlMDI5LTQ5NzMtNDgyNC05ZTgxLTg0MDVjZGM4YjMwMyIsInRpZCI6ImQyMWI3NDc0LTFlN2QtNDBiYS05NWYyLTRkNDViY2U3NmEyYiIsInV0aSI6Ik5DeHptSV9VS0VPN2t4V0dFeUZaQUEiLCJ2ZXIiOiIxLjAifQ.PhUPRGbqsWqVD64NCzvnhF3ly6L_Ab83fNiBqs_xa3dA6QkA5RR17GdLSlkfofE8XDbKvYT2jEMtMn11ljXPbXsTbJo-XvH7v5qqss6F8mPdK4syNUOAecKnCS7XugcWfLU6aCs3R8cfw35_0c1Cextj0W2bA-hWqafmUVLBhD6TYXbPPjYlY2og1fBQWYT0Hn81veFjaC1p5kNj3RA4QHem_YwvrDvywQehSu6zxBZAk3TQcQkv1QkQSLd_WpH89IAwKxY3T-g77s5YWq4qGZH4FFW0ekC3ntZ8wian08EB8sJtJFIGXCbQoGWFUlbdhqt-ntDYiIkO91rLI8oBZQ'}
[2023-12-17T01:53:35.233+0000] {powerbi_dataflow_refresh_operator.py:71} INFO - Refresh dataflow url: https://api.powerbi.com/v1.0/myorg/datasets/fdbac82b-4169-4aaf-80c2-1f6cdde56b46/refreshes
[2023-12-17T01:53:36.875+0000] {powerbi_dataflow_refresh_operator.py:84} INFO - status: 401, data: b''
[2023-12-17T01:53:36.877+0000] {taskinstance.py:1937} ERROR - Task failed with exception
Traceback (most recent call last):
  File "/opt/airflow/plugins/operators/powerbi_dataflow_refresh_operator.py", line 94, in execute
    raise Exception(f"Power BI dataflow refresh failed for Dataflow ID: {self.dataflow_id}")
Exception: Power BI dataflow refresh failed for Dataflow ID: fdbac82b-4169-4aaf-80c2-1f6cdde56b46
[2023-12-17T01:53:36.906+0000] {taskinstance.py:1400} INFO - Marking task as FAILED. dag_id=datalake_refresh_dataflow_powerbi, task_id=taskRefreshDataflowPowerBI, execution_date=20231217T015330, start_date=20231217T015335, end_date=20231217T015336
[2023-12-17T01:53:36.921+0000] {standard_task_runner.py:104} ERROR - Failed to execute job 158 for task taskRefreshDataflowPowerBI (Power BI dataflow refresh failed for Dataflow ID: fdbac82b-4169-4aaf-80c2-1f6cdde56b46; 7443)
[2023-12-17T01:53:36.948+0000] {local_task_job_runner.py:228} INFO - Task exited with return code 1
[2023-12-17T01:53:36.974+0000] {taskinstance.py:2778} INFO - 0 downstream tasks scheduled from follow-on schedule check
