[2023-12-16T15:20:39.956+0000] {taskinstance.py:1159} INFO - Dependencies all met for dep_context=non-requeueable deps ti=<TaskInstance: datalake_refresh_dataflow_powerbi.taskGetTokenMSPowerBi manual__2023-12-16T15:20:38.084046+00:00 [queued]>
[2023-12-16T15:20:39.962+0000] {taskinstance.py:1159} INFO - Dependencies all met for dep_context=requeueable deps ti=<TaskInstance: datalake_refresh_dataflow_powerbi.taskGetTokenMSPowerBi manual__2023-12-16T15:20:38.084046+00:00 [queued]>
[2023-12-16T15:20:39.963+0000] {taskinstance.py:1361} INFO - Starting attempt 1 of 1
[2023-12-16T15:20:39.974+0000] {taskinstance.py:1382} INFO - Executing <Task(PythonOperator): taskGetTokenMSPowerBi> on 2023-12-16 15:20:38.084046+00:00
[2023-12-16T15:20:40.022+0000] {standard_task_runner.py:57} INFO - Started process 3055 to run task
[2023-12-16T15:20:40.024+0000] {standard_task_runner.py:84} INFO - Running: ['***', 'tasks', 'run', 'datalake_refresh_dataflow_powerbi', 'taskGetTokenMSPowerBi', 'manual__2023-12-16T15:20:38.084046+00:00', '--job-id', '126', '--raw', '--subdir', 'DAGS_FOLDER/datalake_refresh_dataflow_powerbi.py', '--cfg-path', '/tmp/tmpfrhuuy6q']
[2023-12-16T15:20:40.025+0000] {standard_task_runner.py:85} INFO - Job 126: Subtask taskGetTokenMSPowerBi
[2023-12-16T15:20:40.065+0000] {task_command.py:416} INFO - Running <TaskInstance: datalake_refresh_dataflow_powerbi.taskGetTokenMSPowerBi manual__2023-12-16T15:20:38.084046+00:00 [running]> on host 83c86e565932
[2023-12-16T15:20:40.114+0000] {taskinstance.py:1662} INFO - Exporting env vars: AIRFLOW_CTX_DAG_EMAIL='christinelee1114@gmail.com' AIRFLOW_CTX_DAG_OWNER='xin' AIRFLOW_CTX_DAG_ID='datalake_refresh_dataflow_powerbi' AIRFLOW_CTX_TASK_ID='taskGetTokenMSPowerBi' AIRFLOW_CTX_EXECUTION_DATE='2023-12-16T15:20:38.084046+00:00' AIRFLOW_CTX_TRY_NUMBER='1' AIRFLOW_CTX_DAG_RUN_ID='manual__2023-12-16T15:20:38.084046+00:00'
[2023-12-16T15:20:40.115+0000] {logging_mixin.py:154} INFO - Getting URL: https://login.microsoftonline.com/d21b7474-1e7d-40ba-95f2-4d45bce76a2b/oauth2/token - data: {'grant_type': 'client_credentials', 'client_id': 'bec41ab8-e33a-4b83-92d6-9d2c957f944c', 'client_secret': 'a726041c-dc22-457b-ac60-9cedfe40d951', 'resource': 'https://analysis.windows.net/powerbi/api'} - encoded_data: b'grant_type=client_credentials&client_id=bec41ab8-e33a-4b83-92d6-9d2c957f944c&client_secret=a726041c-dc22-457b-ac60-9cedfe40d951&resource=https%3A%2F%2Fanalysis.windows.net%2Fpowerbi%2Fapi'
[2023-12-16T15:20:40.510+0000] {taskinstance.py:1937} ERROR - Task failed with exception
Traceback (most recent call last):
  File "/home/airflow/.local/lib/python3.8/site-packages/airflow/operators/python.py", line 192, in execute
    return_value = self.execute_callable()
  File "/home/airflow/.local/lib/python3.8/site-packages/airflow/operators/python.py", line 209, in execute_callable
    return self.python_callable(*self.op_args, **self.op_kwargs)
  File "/opt/airflow/dags/datalake_refresh_dataflow_powerbi.py", line 25, in get_token_microsoft
    access_token = pbHook.get_access_token()
  File "/opt/airflow/plugins/hooks/powerbi_client_credentials_hook.py", line 54, in get_access_token
    raise Exception(f"Failed to obtain Power BI access token. Response: {response_data}")
Exception: Failed to obtain Power BI access token. Response: {'error': 'invalid_client', 'error_description': "AADSTS7000215: Invalid client secret provided. Ensure the secret being sent in the request is the client secret value, not the client secret ID, for a secret added to app 'bec41ab8-e33a-4b83-92d6-9d2c957f944c'. Trace ID: ff880a51-1937-4238-a171-ad02c6072a00 Correlation ID: 4025adc0-d0cd-4ff3-8461-d7511c425d5d Timestamp: 2023-12-16 15:20:40Z", 'error_codes': [7000215], 'timestamp': '2023-12-16 15:20:40Z', 'trace_id': 'ff880a51-1937-4238-a171-ad02c6072a00', 'correlation_id': '4025adc0-d0cd-4ff3-8461-d7511c425d5d', 'error_uri': 'https://login.microsoftonline.com/error?code=7000215'}
[2023-12-16T15:20:40.527+0000] {taskinstance.py:1400} INFO - Marking task as FAILED. dag_id=datalake_refresh_dataflow_powerbi, task_id=taskGetTokenMSPowerBi, execution_date=20231216T152038, start_date=20231216T152039, end_date=20231216T152040
[2023-12-16T15:20:40.536+0000] {warnings.py:109} WARNING - /home/***/.local/lib/python3.8/site-packages/***/utils/email.py:154: RemovedInAirflow3Warning: Fetching SMTP credentials from configuration variables will be deprecated in a future release. Please set credentials using a connection instead.
  send_mime_email(e_from=mail_from, e_to=recipients, mime_msg=msg, conn_id=conn_id, dryrun=dryrun)

[2023-12-16T15:20:40.537+0000] {email.py:270} INFO - Email alerting: attempt 1
[2023-12-16T15:20:40.866+0000] {email.py:270} INFO - Email alerting: attempt 1
[2023-12-16T15:20:41.017+0000] {taskinstance.py:2007} ERROR - Failed to send email to: ['christinelee1114@gmail.com']
Traceback (most recent call last):
  File "/home/airflow/.local/lib/python3.8/site-packages/airflow/models/taskinstance.py", line 1518, in _run_raw_task
    self._execute_task_with_callbacks(context, test_mode, session=session)
  File "/home/airflow/.local/lib/python3.8/site-packages/airflow/models/taskinstance.py", line 1681, in _execute_task_with_callbacks
    result = self._execute_task(context, task_orig)
  File "/home/airflow/.local/lib/python3.8/site-packages/airflow/models/taskinstance.py", line 1744, in _execute_task
    result = execute_callable(context=context, **execute_callable_kwargs)
  File "/home/airflow/.local/lib/python3.8/site-packages/airflow/operators/python.py", line 192, in execute
    return_value = self.execute_callable()
  File "/home/airflow/.local/lib/python3.8/site-packages/airflow/operators/python.py", line 209, in execute_callable
    return self.python_callable(*self.op_args, **self.op_kwargs)
  File "/opt/airflow/dags/datalake_refresh_dataflow_powerbi.py", line 25, in get_token_microsoft
    access_token = pbHook.get_access_token()
  File "/opt/airflow/plugins/hooks/powerbi_client_credentials_hook.py", line 54, in get_access_token
    raise Exception(f"Failed to obtain Power BI access token. Response: {response_data}")
Exception: Failed to obtain Power BI access token. Response: {'error': 'invalid_client', 'error_description': "AADSTS7000215: Invalid client secret provided. Ensure the secret being sent in the request is the client secret value, not the client secret ID, for a secret added to app 'bec41ab8-e33a-4b83-92d6-9d2c957f944c'. Trace ID: ff880a51-1937-4238-a171-ad02c6072a00 Correlation ID: 4025adc0-d0cd-4ff3-8461-d7511c425d5d Timestamp: 2023-12-16 15:20:40Z", 'error_codes': [7000215], 'timestamp': '2023-12-16 15:20:40Z', 'trace_id': 'ff880a51-1937-4238-a171-ad02c6072a00', 'correlation_id': '4025adc0-d0cd-4ff3-8461-d7511c425d5d', 'error_uri': 'https://login.microsoftonline.com/error?code=7000215'}

During handling of the above exception, another exception occurred:

Traceback (most recent call last):
  File "/home/airflow/.local/lib/python3.8/site-packages/airflow/models/taskinstance.py", line 2420, in email_alert
    send_email(task.email, subject, html_content)
  File "/home/airflow/.local/lib/python3.8/site-packages/airflow/utils/email.py", line 80, in send_email
    return backend(
  File "/home/airflow/.local/lib/python3.8/site-packages/airflow/utils/email.py", line 154, in send_email_smtp
    send_mime_email(e_from=mail_from, e_to=recipients, mime_msg=msg, conn_id=conn_id, dryrun=dryrun)
  File "/home/airflow/.local/lib/python3.8/site-packages/airflow/utils/email.py", line 272, in send_mime_email
    smtp_conn = _get_smtp_connection(smtp_host, smtp_port, smtp_timeout, smtp_ssl)
  File "/home/airflow/.local/lib/python3.8/site-packages/airflow/utils/email.py", line 328, in _get_smtp_connection
    return smtplib.SMTP_SSL(host=host, port=port, timeout=timeout, context=ssl_context)
  File "/usr/local/lib/python3.8/smtplib.py", line 1048, in __init__
    SMTP.__init__(self, host, port, local_hostname, timeout,
  File "/usr/local/lib/python3.8/smtplib.py", line 255, in __init__
    (code, msg) = self.connect(host, port)
  File "/usr/local/lib/python3.8/smtplib.py", line 339, in connect
    self.sock = self._get_socket(host, port, self.timeout)
  File "/usr/local/lib/python3.8/smtplib.py", line 1056, in _get_socket
    new_socket = self.context.wrap_socket(new_socket,
  File "/usr/local/lib/python3.8/ssl.py", line 500, in wrap_socket
    return self.sslsocket_class._create(
  File "/usr/local/lib/python3.8/ssl.py", line 1073, in _create
    self.do_handshake()
  File "/usr/local/lib/python3.8/ssl.py", line 1342, in do_handshake
    self._sslobj.do_handshake()
ssl.SSLError: [SSL: WRONG_VERSION_NUMBER] wrong version number (_ssl.c:1131)

During handling of the above exception, another exception occurred:

Traceback (most recent call last):
  File "/home/airflow/.local/lib/python3.8/site-packages/airflow/models/taskinstance.py", line 2005, in handle_failure
    self.email_alert(error, task)
  File "/home/airflow/.local/lib/python3.8/site-packages/airflow/models/taskinstance.py", line 2422, in email_alert
    send_email(task.email, subject, html_content_err)
  File "/home/airflow/.local/lib/python3.8/site-packages/airflow/utils/email.py", line 80, in send_email
    return backend(
  File "/home/airflow/.local/lib/python3.8/site-packages/airflow/utils/email.py", line 154, in send_email_smtp
    send_mime_email(e_from=mail_from, e_to=recipients, mime_msg=msg, conn_id=conn_id, dryrun=dryrun)
  File "/home/airflow/.local/lib/python3.8/site-packages/airflow/utils/email.py", line 272, in send_mime_email
    smtp_conn = _get_smtp_connection(smtp_host, smtp_port, smtp_timeout, smtp_ssl)
  File "/home/airflow/.local/lib/python3.8/site-packages/airflow/utils/email.py", line 328, in _get_smtp_connection
    return smtplib.SMTP_SSL(host=host, port=port, timeout=timeout, context=ssl_context)
  File "/usr/local/lib/python3.8/smtplib.py", line 1048, in __init__
    SMTP.__init__(self, host, port, local_hostname, timeout,
  File "/usr/local/lib/python3.8/smtplib.py", line 255, in __init__
    (code, msg) = self.connect(host, port)
  File "/usr/local/lib/python3.8/smtplib.py", line 339, in connect
    self.sock = self._get_socket(host, port, self.timeout)
  File "/usr/local/lib/python3.8/smtplib.py", line 1056, in _get_socket
    new_socket = self.context.wrap_socket(new_socket,
  File "/usr/local/lib/python3.8/ssl.py", line 500, in wrap_socket
    return self.sslsocket_class._create(
  File "/usr/local/lib/python3.8/ssl.py", line 1073, in _create
    self.do_handshake()
  File "/usr/local/lib/python3.8/ssl.py", line 1342, in do_handshake
    self._sslobj.do_handshake()
ssl.SSLError: [SSL: WRONG_VERSION_NUMBER] wrong version number (_ssl.c:1131)
[2023-12-16T15:20:41.039+0000] {standard_task_runner.py:104} ERROR - Failed to execute job 126 for task taskGetTokenMSPowerBi (Failed to obtain Power BI access token. Response: {'error': 'invalid_client', 'error_description': "AADSTS7000215: Invalid client secret provided. Ensure the secret being sent in the request is the client secret value, not the client secret ID, for a secret added to app 'bec41ab8-e33a-4b83-92d6-9d2c957f944c'. Trace ID: ff880a51-1937-4238-a171-ad02c6072a00 Correlation ID: 4025adc0-d0cd-4ff3-8461-d7511c425d5d Timestamp: 2023-12-16 15:20:40Z", 'error_codes': [7000215], 'timestamp': '2023-12-16 15:20:40Z', 'trace_id': 'ff880a51-1937-4238-a171-ad02c6072a00', 'correlation_id': '4025adc0-d0cd-4ff3-8461-d7511c425d5d', 'error_uri': 'https://login.microsoftonline.com/error?code=7000215'}; 3055)
[2023-12-16T15:20:41.083+0000] {local_task_job_runner.py:228} INFO - Task exited with return code 1
[2023-12-16T15:20:41.105+0000] {taskinstance.py:2778} INFO - 0 downstream tasks scheduled from follow-on schedule check
