[2023-12-12T14:50:19.916+0000] {taskinstance.py:1159} INFO - Dependencies all met for dep_context=non-requeueable deps ti=<TaskInstance: conn_db_run.conn_local_db manual__2023-12-12T14:50:18.617663+00:00 [queued]>
[2023-12-12T14:50:19.922+0000] {taskinstance.py:1159} INFO - Dependencies all met for dep_context=requeueable deps ti=<TaskInstance: conn_db_run.conn_local_db manual__2023-12-12T14:50:18.617663+00:00 [queued]>
[2023-12-12T14:50:19.922+0000] {taskinstance.py:1361} INFO - Starting attempt 1 of 1
[2023-12-12T14:50:19.931+0000] {taskinstance.py:1382} INFO - Executing <Task(_PythonDecoratedOperator): conn_local_db> on 2023-12-12 14:50:18.617663+00:00
[2023-12-12T14:50:19.937+0000] {standard_task_runner.py:57} INFO - Started process 4679 to run task
[2023-12-12T14:50:19.939+0000] {standard_task_runner.py:84} INFO - Running: ['***', 'tasks', 'run', 'conn_db_run', 'conn_local_db', 'manual__2023-12-12T14:50:18.617663+00:00', '--job-id', '91', '--raw', '--subdir', 'DAGS_FOLDER/test_postgres_1212.py', '--cfg-path', '/tmp/tmpjsxknae8']
[2023-12-12T14:50:19.942+0000] {standard_task_runner.py:85} INFO - Job 91: Subtask conn_local_db
[2023-12-12T14:50:19.975+0000] {task_command.py:416} INFO - Running <TaskInstance: conn_db_run.conn_local_db manual__2023-12-12T14:50:18.617663+00:00 [running]> on host 7fd8dd875aa1
[2023-12-12T14:50:20.022+0000] {taskinstance.py:1662} INFO - Exporting env vars: AIRFLOW_CTX_DAG_OWNER='***' AIRFLOW_CTX_DAG_ID='conn_db_run' AIRFLOW_CTX_TASK_ID='conn_local_db' AIRFLOW_CTX_EXECUTION_DATE='2023-12-12T14:50:18.617663+00:00' AIRFLOW_CTX_TRY_NUMBER='1' AIRFLOW_CTX_DAG_RUN_ID='manual__2023-12-12T14:50:18.617663+00:00'
[2023-12-12T14:50:20.028+0000] {base.py:73} INFO - Using connection ID 'postgres_conn' for task execution.
[2023-12-12T14:50:20.029+0000] {taskinstance.py:1937} ERROR - Task failed with exception
Traceback (most recent call last):
  File "/home/airflow/.local/lib/python3.8/site-packages/airflow/decorators/base.py", line 221, in execute
    return_value = super().execute(context)
  File "/home/airflow/.local/lib/python3.8/site-packages/airflow/operators/python.py", line 192, in execute
    return_value = self.execute_callable()
  File "/home/airflow/.local/lib/python3.8/site-packages/airflow/operators/python.py", line 209, in execute_callable
    return self.python_callable(*self.op_args, **self.op_kwargs)
  File "/opt/airflow/dags/test_postgres_1212.py", line 12, in conn_local_db
    connection = hook.get_conn()
  File "/home/airflow/.local/lib/python3.8/site-packages/airflow/providers/postgres/hooks/postgres.py", line 155, in get_conn
    self.conn = psycopg2.connect(**conn_args)
  File "/home/airflow/.local/lib/python3.8/site-packages/psycopg2/__init__.py", line 122, in connect
    conn = _connect(dsn, connection_factory=connection_factory, **kwasync)
psycopg2.OperationalError: connection to server at "localhost" (127.0.0.1), port 5432 failed: Connection refused
	Is the server running on that host and accepting TCP/IP connections?
connection to server at "localhost" (::1), port 5432 failed: Cannot assign requested address
	Is the server running on that host and accepting TCP/IP connections?

[2023-12-12T14:50:20.039+0000] {taskinstance.py:1400} INFO - Marking task as FAILED. dag_id=conn_db_run, task_id=conn_local_db, execution_date=20231212T145018, start_date=20231212T145019, end_date=20231212T145020
[2023-12-12T14:50:20.047+0000] {standard_task_runner.py:104} ERROR - Failed to execute job 91 for task conn_local_db (connection to server at "localhost" (127.0.0.1), port 5432 failed: Connection refused
	Is the server running on that host and accepting TCP/IP connections?
connection to server at "localhost" (::1), port 5432 failed: Cannot assign requested address
	Is the server running on that host and accepting TCP/IP connections?
; 4679)
[2023-12-12T14:50:20.072+0000] {local_task_job_runner.py:228} INFO - Task exited with return code 1
[2023-12-12T14:50:20.085+0000] {taskinstance.py:2778} INFO - 0 downstream tasks scheduled from follow-on schedule check
