[2023-12-12T13:25:57.565+0000] {taskinstance.py:1159} INFO - Dependencies all met for dep_context=non-requeueable deps ti=<TaskInstance: crawl_and_store_to_mysql_01.store_csv_to_mysql scheduled__2023-12-11T13:20:36.154790+00:00 [queued]>
[2023-12-12T13:25:57.574+0000] {taskinstance.py:1159} INFO - Dependencies all met for dep_context=requeueable deps ti=<TaskInstance: crawl_and_store_to_mysql_01.store_csv_to_mysql scheduled__2023-12-11T13:20:36.154790+00:00 [queued]>
[2023-12-12T13:25:57.574+0000] {taskinstance.py:1361} INFO - Starting attempt 2 of 2
[2023-12-12T13:25:57.585+0000] {taskinstance.py:1382} INFO - Executing <Task(PythonOperator): store_csv_to_mysql> on 2023-12-11 13:20:36.154790+00:00
[2023-12-12T13:25:57.590+0000] {standard_task_runner.py:57} INFO - Started process 3368 to run task
[2023-12-12T13:25:57.594+0000] {standard_task_runner.py:84} INFO - Running: ['***', 'tasks', 'run', 'crawl_and_store_to_mysql_01', 'store_csv_to_mysql', 'scheduled__2023-12-11T13:20:36.154790+00:00', '--job-id', '81', '--raw', '--subdir', 'DAGS_FOLDER/download_cctv_data.py', '--cfg-path', '/tmp/tmpftuqqj93']
[2023-12-12T13:25:57.597+0000] {standard_task_runner.py:85} INFO - Job 81: Subtask store_csv_to_mysql
[2023-12-12T13:25:57.638+0000] {task_command.py:416} INFO - Running <TaskInstance: crawl_and_store_to_mysql_01.store_csv_to_mysql scheduled__2023-12-11T13:20:36.154790+00:00 [running]> on host 7fd8dd875aa1
[2023-12-12T13:25:57.691+0000] {taskinstance.py:1662} INFO - Exporting env vars: AIRFLOW_CTX_DAG_OWNER='xin' AIRFLOW_CTX_DAG_ID='crawl_and_store_to_mysql_01' AIRFLOW_CTX_TASK_ID='store_csv_to_mysql' AIRFLOW_CTX_EXECUTION_DATE='2023-12-11T13:20:36.154790+00:00' AIRFLOW_CTX_TRY_NUMBER='2' AIRFLOW_CTX_DAG_RUN_ID='scheduled__2023-12-11T13:20:36.154790+00:00'
[2023-12-12T13:25:57.694+0000] {taskinstance.py:1937} ERROR - Task failed with exception
Traceback (most recent call last):
  File "/home/airflow/.local/lib/python3.8/site-packages/pymysql/connections.py", line 644, in connect
    sock = socket.create_connection(
  File "/usr/local/lib/python3.8/socket.py", line 808, in create_connection
    raise err
  File "/usr/local/lib/python3.8/socket.py", line 796, in create_connection
    sock.connect(sa)
OSError: [Errno 99] Cannot assign requested address

During handling of the above exception, another exception occurred:

Traceback (most recent call last):
  File "/home/airflow/.local/lib/python3.8/site-packages/airflow/operators/python.py", line 192, in execute
    return_value = self.execute_callable()
  File "/home/airflow/.local/lib/python3.8/site-packages/airflow/operators/python.py", line 209, in execute_callable
    return self.python_callable(*self.op_args, **self.op_kwargs)
  File "/opt/airflow/dags/download_cctv_data.py", line 120, in store_csv_to_mysql
    connection = pymysql.connect(
  File "/home/airflow/.local/lib/python3.8/site-packages/pymysql/connections.py", line 358, in __init__
    self.connect()
  File "/home/airflow/.local/lib/python3.8/site-packages/pymysql/connections.py", line 711, in connect
    raise exc
pymysql.err.OperationalError: (2003, "Can't connect to MySQL server on 'localhost' ([Errno 99] Cannot assign requested address)")
[2023-12-12T13:25:57.704+0000] {taskinstance.py:1400} INFO - Marking task as FAILED. dag_id=crawl_and_store_to_mysql_01, task_id=store_csv_to_mysql, execution_date=20231211T132036, start_date=20231212T132557, end_date=20231212T132557
[2023-12-12T13:25:57.712+0000] {standard_task_runner.py:104} ERROR - Failed to execute job 81 for task store_csv_to_mysql ((2003, "Can't connect to MySQL server on 'localhost' ([Errno 99] Cannot assign requested address)"); 3368)
[2023-12-12T13:25:57.726+0000] {local_task_job_runner.py:228} INFO - Task exited with return code 1
[2023-12-12T13:25:57.739+0000] {taskinstance.py:2778} INFO - 0 downstream tasks scheduled from follow-on schedule check
