[2023-12-16T16:37:18.238+0000] {taskinstance.py:1159} INFO - Dependencies all met for dep_context=non-requeueable deps ti=<TaskInstance: datalake_refresh_dataflow_powerbi.taskRefreshDataflowPowerBI manual__2023-12-16T16:37:14.560783+00:00 [queued]>
[2023-12-16T16:37:18.249+0000] {taskinstance.py:1159} INFO - Dependencies all met for dep_context=requeueable deps ti=<TaskInstance: datalake_refresh_dataflow_powerbi.taskRefreshDataflowPowerBI manual__2023-12-16T16:37:14.560783+00:00 [queued]>
[2023-12-16T16:37:18.249+0000] {taskinstance.py:1361} INFO - Starting attempt 1 of 1
[2023-12-16T16:37:18.262+0000] {taskinstance.py:1382} INFO - Executing <Task(PowerBIDataflowRefreshOperator): taskRefreshDataflowPowerBI> on 2023-12-16 16:37:14.560783+00:00
[2023-12-16T16:37:18.268+0000] {standard_task_runner.py:57} INFO - Started process 4276 to run task
[2023-12-16T16:37:18.270+0000] {standard_task_runner.py:84} INFO - Running: ['***', 'tasks', 'run', 'datalake_refresh_dataflow_powerbi', 'taskRefreshDataflowPowerBI', 'manual__2023-12-16T16:37:14.560783+00:00', '--job-id', '148', '--raw', '--subdir', 'DAGS_FOLDER/datalake_refresh_dataflow_powerbi.py', '--cfg-path', '/tmp/tmpipmqcrz1']
[2023-12-16T16:37:18.272+0000] {standard_task_runner.py:85} INFO - Job 148: Subtask taskRefreshDataflowPowerBI
[2023-12-16T16:37:18.311+0000] {task_command.py:416} INFO - Running <TaskInstance: datalake_refresh_dataflow_powerbi.taskRefreshDataflowPowerBI manual__2023-12-16T16:37:14.560783+00:00 [running]> on host 83c86e565932
[2023-12-16T16:37:18.377+0000] {taskinstance.py:1662} INFO - Exporting env vars: AIRFLOW_CTX_DAG_EMAIL='christinelee1114@gmail.com' AIRFLOW_CTX_DAG_OWNER='xin' AIRFLOW_CTX_DAG_ID='datalake_refresh_dataflow_powerbi' AIRFLOW_CTX_TASK_ID='taskRefreshDataflowPowerBI' AIRFLOW_CTX_EXECUTION_DATE='2023-12-16T16:37:14.560783+00:00' AIRFLOW_CTX_TRY_NUMBER='1' AIRFLOW_CTX_DAG_RUN_ID='manual__2023-12-16T16:37:14.560783+00:00'
[2023-12-16T16:37:18.378+0000] {powerbi_dataflow_refresh_operator.py:88} INFO - Calling API Dataflow ID: fdbac82b-4169-4aaf-80c2-1f6cdde56b46
[2023-12-16T16:37:18.378+0000] {logging_mixin.py:154} INFO - Refresh dataflow url: https://api.powerbi.com/v1.0/myorg/groups/f0125acd-c70f-4c8d-b882-288ae72edc18/datasets/fdbac82b-4169-4aaf-80c2-1f6cdde56b46/refreshes - headers: {'Content-Type': 'application/json', 'Authorization': 'Bearer eyJ0eXAiOiJKV1QiLCJhbGciOiJSUzI1NiIsIng1dCI6IlQxU3QtZExUdnlXUmd4Ql82NzZ1OGtyWFMtSSIsImtpZCI6IlQxU3QtZExUdnlXUmd4Ql82NzZ1OGtyWFMtSSJ9.eyJhdWQiOiJodHRwczovL2FuYWx5c2lzLndpbmRvd3MubmV0L3Bvd2VyYmkvYXBpIiwiaXNzIjoiaHR0cHM6Ly9zdHMud2luZG93cy5uZXQvZDIxYjc0NzQtMWU3ZC00MGJhLTk1ZjItNGQ0NWJjZTc2YTJiLyIsImlhdCI6MTcwMjc0NDMzNywibmJmIjoxNzAyNzQ0MzM3LCJleHAiOjE3MDI3NDgyMzcsImFpbyI6IkUyVmdZS2hmNWh0aFA2RXlZSkhmUmUrOWpWLzVBQT09IiwiYXBwaWQiOiJiZWM0MWFiOC1lMzNhLTRiODMtOTJkNi05ZDJjOTU3Zjk0NGMiLCJhcHBpZGFjciI6IjEiLCJpZHAiOiJodHRwczovL3N0cy53aW5kb3dzLm5ldC9kMjFiNzQ3NC0xZTdkLTQwYmEtOTVmMi00ZDQ1YmNlNzZhMmIvIiwiaWR0eXAiOiJhcHAiLCJvaWQiOiJlY2FlZTAyOS00OTczLTQ4MjQtOWU4MS04NDA1Y2RjOGIzMDMiLCJyaCI6IjAuQVhJQWRIUWIwbjBldWtDVjhrMUZ2T2RxS3drQUFBQUFBQUFBd0FBQUFBQUFBQUREQUFBLiIsInN1YiI6ImVjYWVlMDI5LTQ5NzMtNDgyNC05ZTgxLTg0MDVjZGM4YjMwMyIsInRpZCI6ImQyMWI3NDc0LTFlN2QtNDBiYS05NWYyLTRkNDViY2U3NmEyYiIsInV0aSI6IllWaGlSQ3RNSWtLSnZsRHNwZ2h0QUEiLCJ2ZXIiOiIxLjAifQ.S1K_SeML3kUpoixR798fDZtv4EIENJ91BI8kR5DQ9tVmhjm8dzRb0KIOxhzN8bg5XLCc2S3SivO3dZkJJtE58wFccjPNFHjKqWG68liE09kiaOmQ623Yp77alKuImh91yN2wKzbhY542u9b4IC5I0p-DWmHJcPZ_f-x9nb-2tPMeyAv-ou5PdLKeOXuKZR9lVlGpFDENKWirgELu_EEwDqbq_LBWtvoBH9DZg6tkkgUVj4EDCtfYqczSqy8QlGN_RJz3DAwrCEjzETb0HI1qInGKpaSzUiNPCLtrDULq1a3zyS8pXToIkgs-le2XfW3oC8SWNUaBoN9VA6E5EjZ-CA'}
[2023-12-16T16:37:18.379+0000] {powerbi_dataflow_refresh_operator.py:71} INFO - Refresh dataflow url: https://api.powerbi.com/v1.0/myorg/groups/f0125acd-c70f-4c8d-b882-288ae72edc18/datasets/fdbac82b-4169-4aaf-80c2-1f6cdde56b46/refreshes
[2023-12-16T16:37:20.643+0000] {powerbi_dataflow_refresh_operator.py:84} INFO - status: 401, data: b''
[2023-12-16T16:37:20.645+0000] {taskinstance.py:1937} ERROR - Task failed with exception
Traceback (most recent call last):
  File "/opt/airflow/plugins/operators/powerbi_dataflow_refresh_operator.py", line 94, in execute
    raise Exception(f"Power BI dataflow refresh failed for Dataflow ID: {self.dataflow_id}")
Exception: Power BI dataflow refresh failed for Dataflow ID: fdbac82b-4169-4aaf-80c2-1f6cdde56b46
[2023-12-16T16:37:20.659+0000] {taskinstance.py:1400} INFO - Marking task as FAILED. dag_id=datalake_refresh_dataflow_powerbi, task_id=taskRefreshDataflowPowerBI, execution_date=20231216T163714, start_date=20231216T163718, end_date=20231216T163720
[2023-12-16T16:37:20.668+0000] {warnings.py:109} WARNING - /home/***/.local/lib/python3.8/site-packages/***/utils/email.py:154: RemovedInAirflow3Warning: Fetching SMTP credentials from configuration variables will be deprecated in a future release. Please set credentials using a connection instead.
  send_mime_email(e_from=mail_from, e_to=recipients, mime_msg=msg, conn_id=conn_id, dryrun=dryrun)

[2023-12-16T16:37:20.669+0000] {email.py:270} INFO - Email alerting: attempt 1
[2023-12-16T16:37:21.426+0000] {email.py:270} INFO - Email alerting: attempt 1
[2023-12-16T16:37:22.157+0000] {taskinstance.py:2007} ERROR - Failed to send email to: ['christinelee1114@gmail.com']
Traceback (most recent call last):
  File "/home/airflow/.local/lib/python3.8/site-packages/airflow/models/taskinstance.py", line 1518, in _run_raw_task
    self._execute_task_with_callbacks(context, test_mode, session=session)
  File "/home/airflow/.local/lib/python3.8/site-packages/airflow/models/taskinstance.py", line 1681, in _execute_task_with_callbacks
    result = self._execute_task(context, task_orig)
  File "/home/airflow/.local/lib/python3.8/site-packages/airflow/models/taskinstance.py", line 1744, in _execute_task
    result = execute_callable(context=context, **execute_callable_kwargs)
  File "/opt/airflow/plugins/operators/powerbi_dataflow_refresh_operator.py", line 94, in execute
    raise Exception(f"Power BI dataflow refresh failed for Dataflow ID: {self.dataflow_id}")
Exception: Power BI dataflow refresh failed for Dataflow ID: fdbac82b-4169-4aaf-80c2-1f6cdde56b46

During handling of the above exception, another exception occurred:

Traceback (most recent call last):
  File "/home/airflow/.local/lib/python3.8/site-packages/airflow/models/taskinstance.py", line 2420, in email_alert
    send_email(task.email, subject, html_content)
  File "/home/airflow/.local/lib/python3.8/site-packages/airflow/utils/email.py", line 80, in send_email
    return backend(
  File "/home/airflow/.local/lib/python3.8/site-packages/airflow/utils/email.py", line 154, in send_email_smtp
    send_mime_email(e_from=mail_from, e_to=recipients, mime_msg=msg, conn_id=conn_id, dryrun=dryrun)
  File "/home/airflow/.local/lib/python3.8/site-packages/airflow/utils/email.py", line 272, in send_mime_email
    smtp_conn = _get_smtp_connection(smtp_host, smtp_port, smtp_timeout, smtp_ssl)
  File "/home/airflow/.local/lib/python3.8/site-packages/airflow/utils/email.py", line 328, in _get_smtp_connection
    return smtplib.SMTP_SSL(host=host, port=port, timeout=timeout, context=ssl_context)
  File "/usr/local/lib/python3.8/smtplib.py", line 1048, in __init__
    SMTP.__init__(self, host, port, local_hostname, timeout,
  File "/usr/local/lib/python3.8/smtplib.py", line 255, in __init__
    (code, msg) = self.connect(host, port)
  File "/usr/local/lib/python3.8/smtplib.py", line 339, in connect
    self.sock = self._get_socket(host, port, self.timeout)
  File "/usr/local/lib/python3.8/smtplib.py", line 1056, in _get_socket
    new_socket = self.context.wrap_socket(new_socket,
  File "/usr/local/lib/python3.8/ssl.py", line 500, in wrap_socket
    return self.sslsocket_class._create(
  File "/usr/local/lib/python3.8/ssl.py", line 1073, in _create
    self.do_handshake()
  File "/usr/local/lib/python3.8/ssl.py", line 1342, in do_handshake
    self._sslobj.do_handshake()
ssl.SSLError: [SSL: WRONG_VERSION_NUMBER] wrong version number (_ssl.c:1131)

During handling of the above exception, another exception occurred:

Traceback (most recent call last):
  File "/home/airflow/.local/lib/python3.8/site-packages/airflow/models/taskinstance.py", line 2005, in handle_failure
    self.email_alert(error, task)
  File "/home/airflow/.local/lib/python3.8/site-packages/airflow/models/taskinstance.py", line 2422, in email_alert
    send_email(task.email, subject, html_content_err)
  File "/home/airflow/.local/lib/python3.8/site-packages/airflow/utils/email.py", line 80, in send_email
    return backend(
  File "/home/airflow/.local/lib/python3.8/site-packages/airflow/utils/email.py", line 154, in send_email_smtp
    send_mime_email(e_from=mail_from, e_to=recipients, mime_msg=msg, conn_id=conn_id, dryrun=dryrun)
  File "/home/airflow/.local/lib/python3.8/site-packages/airflow/utils/email.py", line 272, in send_mime_email
    smtp_conn = _get_smtp_connection(smtp_host, smtp_port, smtp_timeout, smtp_ssl)
  File "/home/airflow/.local/lib/python3.8/site-packages/airflow/utils/email.py", line 328, in _get_smtp_connection
    return smtplib.SMTP_SSL(host=host, port=port, timeout=timeout, context=ssl_context)
  File "/usr/local/lib/python3.8/smtplib.py", line 1048, in __init__
    SMTP.__init__(self, host, port, local_hostname, timeout,
  File "/usr/local/lib/python3.8/smtplib.py", line 255, in __init__
    (code, msg) = self.connect(host, port)
  File "/usr/local/lib/python3.8/smtplib.py", line 339, in connect
    self.sock = self._get_socket(host, port, self.timeout)
  File "/usr/local/lib/python3.8/smtplib.py", line 1056, in _get_socket
    new_socket = self.context.wrap_socket(new_socket,
  File "/usr/local/lib/python3.8/ssl.py", line 500, in wrap_socket
    return self.sslsocket_class._create(
  File "/usr/local/lib/python3.8/ssl.py", line 1073, in _create
    self.do_handshake()
  File "/usr/local/lib/python3.8/ssl.py", line 1342, in do_handshake
    self._sslobj.do_handshake()
ssl.SSLError: [SSL: WRONG_VERSION_NUMBER] wrong version number (_ssl.c:1131)
[2023-12-16T16:37:22.176+0000] {standard_task_runner.py:104} ERROR - Failed to execute job 148 for task taskRefreshDataflowPowerBI (Power BI dataflow refresh failed for Dataflow ID: fdbac82b-4169-4aaf-80c2-1f6cdde56b46; 4276)
[2023-12-16T16:37:22.190+0000] {local_task_job_runner.py:228} INFO - Task exited with return code 1
[2023-12-16T16:37:22.207+0000] {taskinstance.py:2778} INFO - 0 downstream tasks scheduled from follow-on schedule check
