[2023-12-20T04:19:24.120+0000] {taskinstance.py:1159} INFO - Dependencies all met for dep_context=non-requeueable deps ti=<TaskInstance: service_oriented_class_project.safetyWarning_etl manual__2023-12-20T04:19:20.734599+00:00 [queued]>
[2023-12-20T04:19:24.129+0000] {taskinstance.py:1159} INFO - Dependencies all met for dep_context=requeueable deps ti=<TaskInstance: service_oriented_class_project.safetyWarning_etl manual__2023-12-20T04:19:20.734599+00:00 [queued]>
[2023-12-20T04:19:24.130+0000] {taskinstance.py:1361} INFO - Starting attempt 1 of 1
[2023-12-20T04:19:24.141+0000] {taskinstance.py:1382} INFO - Executing <Task(PythonOperator): safetyWarning_etl> on 2023-12-20 04:19:20.734599+00:00
[2023-12-20T04:19:24.150+0000] {standard_task_runner.py:57} INFO - Started process 18653 to run task
[2023-12-20T04:19:24.153+0000] {standard_task_runner.py:84} INFO - Running: ['***', 'tasks', 'run', 'service_oriented_class_project', 'safetyWarning_etl', 'manual__2023-12-20T04:19:20.734599+00:00', '--job-id', '478', '--raw', '--subdir', 'DAGS_FOLDER/service_oriented_class_project.py', '--cfg-path', '/tmp/tmpu4gopsz4']
[2023-12-20T04:19:24.156+0000] {standard_task_runner.py:85} INFO - Job 478: Subtask safetyWarning_etl
[2023-12-20T04:19:24.198+0000] {task_command.py:416} INFO - Running <TaskInstance: service_oriented_class_project.safetyWarning_etl manual__2023-12-20T04:19:20.734599+00:00 [running]> on host f97daee24bd9
[2023-12-20T04:19:24.270+0000] {taskinstance.py:1662} INFO - Exporting env vars: AIRFLOW_CTX_DAG_EMAIL='christinelee1114@gmail.com' AIRFLOW_CTX_DAG_OWNER='xin' AIRFLOW_CTX_DAG_ID='service_oriented_class_project' AIRFLOW_CTX_TASK_ID='safetyWarning_etl' AIRFLOW_CTX_EXECUTION_DATE='2023-12-20T04:19:20.734599+00:00' AIRFLOW_CTX_TRY_NUMBER='1' AIRFLOW_CTX_DAG_RUN_ID='manual__2023-12-20T04:19:20.734599+00:00'
[2023-12-20T04:19:24.298+0000] {taskinstance.py:1937} ERROR - Task failed with exception
Traceback (most recent call last):
  File "/home/airflow/.local/lib/python3.8/site-packages/airflow/operators/python.py", line 192, in execute
    return_value = self.execute_callable()
  File "/home/airflow/.local/lib/python3.8/site-packages/airflow/operators/python.py", line 209, in execute_callable
    return self.python_callable(*self.op_args, **self.op_kwargs)
  File "/opt/airflow/dags/service_oriented_class_project.py", line 283, in safetyWarning_etl
    geolocator = Nominatim(user_agent="my_geocoder")
NameError: name 'Nominatim' is not defined
[2023-12-20T04:19:24.312+0000] {taskinstance.py:1400} INFO - Marking task as FAILED. dag_id=service_oriented_class_project, task_id=safetyWarning_etl, execution_date=20231220T041920, start_date=20231220T041924, end_date=20231220T041924
[2023-12-20T04:19:24.324+0000] {standard_task_runner.py:104} ERROR - Failed to execute job 478 for task safetyWarning_etl (name 'Nominatim' is not defined; 18653)
[2023-12-20T04:19:24.367+0000] {local_task_job_runner.py:228} INFO - Task exited with return code 1
[2023-12-20T04:19:24.388+0000] {taskinstance.py:2778} INFO - 0 downstream tasks scheduled from follow-on schedule check
