[2023-12-12T15:11:24.080+0000] {taskinstance.py:1159} INFO - Dependencies all met for dep_context=non-requeueable deps ti=<TaskInstance: conn_db_run.conn_local_db manual__2023-12-12T15:11:22.617768+00:00 [queued]>
[2023-12-12T15:11:24.086+0000] {taskinstance.py:1159} INFO - Dependencies all met for dep_context=requeueable deps ti=<TaskInstance: conn_db_run.conn_local_db manual__2023-12-12T15:11:22.617768+00:00 [queued]>
[2023-12-12T15:11:24.087+0000] {taskinstance.py:1361} INFO - Starting attempt 1 of 1
[2023-12-12T15:11:24.097+0000] {taskinstance.py:1382} INFO - Executing <Task(_PythonDecoratedOperator): conn_local_db> on 2023-12-12 15:11:22.617768+00:00
[2023-12-12T15:11:24.105+0000] {standard_task_runner.py:57} INFO - Started process 5019 to run task
[2023-12-12T15:11:24.107+0000] {standard_task_runner.py:84} INFO - Running: ['***', 'tasks', 'run', 'conn_db_run', 'conn_local_db', 'manual__2023-12-12T15:11:22.617768+00:00', '--job-id', '97', '--raw', '--subdir', 'DAGS_FOLDER/test_postgres_1212.py', '--cfg-path', '/tmp/tmpfl6fuwck']
[2023-12-12T15:11:24.110+0000] {standard_task_runner.py:85} INFO - Job 97: Subtask conn_local_db
[2023-12-12T15:11:24.151+0000] {task_command.py:416} INFO - Running <TaskInstance: conn_db_run.conn_local_db manual__2023-12-12T15:11:22.617768+00:00 [running]> on host 7fd8dd875aa1
[2023-12-12T15:11:24.203+0000] {taskinstance.py:1662} INFO - Exporting env vars: AIRFLOW_CTX_DAG_OWNER='***' AIRFLOW_CTX_DAG_ID='conn_db_run' AIRFLOW_CTX_TASK_ID='conn_local_db' AIRFLOW_CTX_EXECUTION_DATE='2023-12-12T15:11:22.617768+00:00' AIRFLOW_CTX_TRY_NUMBER='1' AIRFLOW_CTX_DAG_RUN_ID='manual__2023-12-12T15:11:22.617768+00:00'
[2023-12-12T15:11:24.211+0000] {base.py:73} INFO - Using connection ID 'postgres_conn' for task execution.
[2023-12-12T15:11:24.253+0000] {taskinstance.py:1937} ERROR - Task failed with exception
Traceback (most recent call last):
  File "/home/airflow/.local/lib/python3.8/site-packages/airflow/decorators/base.py", line 221, in execute
    return_value = super().execute(context)
  File "/home/airflow/.local/lib/python3.8/site-packages/airflow/operators/python.py", line 192, in execute
    return_value = self.execute_callable()
  File "/home/airflow/.local/lib/python3.8/site-packages/airflow/operators/python.py", line 209, in execute_callable
    return self.python_callable(*self.op_args, **self.op_kwargs)
  File "/opt/airflow/dags/test_postgres_1212.py", line 21, in conn_local_db
    return json.dumps(float(result))
TypeError: float() argument must be a string or a number, not 'list'
[2023-12-12T15:11:24.264+0000] {taskinstance.py:1400} INFO - Marking task as FAILED. dag_id=conn_db_run, task_id=conn_local_db, execution_date=20231212T151122, start_date=20231212T151124, end_date=20231212T151124
[2023-12-12T15:11:24.275+0000] {standard_task_runner.py:104} ERROR - Failed to execute job 97 for task conn_local_db (float() argument must be a string or a number, not 'list'; 5019)
[2023-12-12T15:11:24.320+0000] {local_task_job_runner.py:228} INFO - Task exited with return code 1
[2023-12-12T15:11:24.334+0000] {taskinstance.py:2778} INFO - 0 downstream tasks scheduled from follow-on schedule check
