[2023-12-14T13:59:31.321+0000] {taskinstance.py:1159} INFO - Dependencies all met for dep_context=non-requeueable deps ti=<TaskInstance: download_cctv_data_to_postgresql.delete_data manual__2023-12-14T13:59:26.056574+00:00 [queued]>
[2023-12-14T13:59:31.329+0000] {taskinstance.py:1159} INFO - Dependencies all met for dep_context=requeueable deps ti=<TaskInstance: download_cctv_data_to_postgresql.delete_data manual__2023-12-14T13:59:26.056574+00:00 [queued]>
[2023-12-14T13:59:31.330+0000] {taskinstance.py:1361} INFO - Starting attempt 1 of 1
[2023-12-14T13:59:31.341+0000] {taskinstance.py:1382} INFO - Executing <Task(PostgresOperator): delete_data> on 2023-12-14 13:59:26.056574+00:00
[2023-12-14T13:59:31.347+0000] {standard_task_runner.py:57} INFO - Started process 193 to run task
[2023-12-14T13:59:31.349+0000] {standard_task_runner.py:84} INFO - Running: ['***', 'tasks', 'run', 'download_cctv_data_to_postgresql', 'delete_data', 'manual__2023-12-14T13:59:26.056574+00:00', '--job-id', '10', '--raw', '--subdir', 'DAGS_FOLDER/download_cctv_data_to_postgresql.py', '--cfg-path', '/tmp/tmpy26hefym']
[2023-12-14T13:59:31.352+0000] {standard_task_runner.py:85} INFO - Job 10: Subtask delete_data
[2023-12-14T13:59:31.390+0000] {task_command.py:416} INFO - Running <TaskInstance: download_cctv_data_to_postgresql.delete_data manual__2023-12-14T13:59:26.056574+00:00 [running]> on host cbe761bfd41f
[2023-12-14T13:59:31.446+0000] {taskinstance.py:1662} INFO - Exporting env vars: AIRFLOW_CTX_DAG_EMAIL='christinelee1114@gmail.com' AIRFLOW_CTX_DAG_OWNER='xin' AIRFLOW_CTX_DAG_ID='download_cctv_data_to_postgresql' AIRFLOW_CTX_TASK_ID='delete_data' AIRFLOW_CTX_EXECUTION_DATE='2023-12-14T13:59:26.056574+00:00' AIRFLOW_CTX_TRY_NUMBER='1' AIRFLOW_CTX_DAG_RUN_ID='manual__2023-12-14T13:59:26.056574+00:00'
[2023-12-14T13:59:31.448+0000] {sql.py:274} INFO - Executing: DROP TABLE IF EXISTS cctv;
[2023-12-14T13:59:31.455+0000] {base.py:73} INFO - Using connection ID 'postgres_conn' for task execution.
[2023-12-14T13:59:31.463+0000] {base.py:73} INFO - Using connection ID 'postgres_conn' for task execution.
[2023-12-14T13:59:31.538+0000] {taskinstance.py:1937} ERROR - Task failed with exception
Traceback (most recent call last):
  File "/home/airflow/.local/lib/python3.8/site-packages/airflow/providers/common/sql/operators/sql.py", line 280, in execute
    output = hook.run(
  File "/home/airflow/.local/lib/python3.8/site-packages/airflow/providers/common/sql/hooks/sql.py", line 385, in run
    with closing(self.get_conn()) as conn:
  File "/home/airflow/.local/lib/python3.8/site-packages/airflow/providers/postgres/hooks/postgres.py", line 155, in get_conn
    self.conn = psycopg2.connect(**conn_args)
  File "/home/airflow/.local/lib/python3.8/site-packages/psycopg2/__init__.py", line 122, in connect
    conn = _connect(dsn, connection_factory=connection_factory, **kwasync)
psycopg2.OperationalError: could not translate host name "host.docker.local" to address: Name or service not known

[2023-12-14T13:59:31.548+0000] {taskinstance.py:1400} INFO - Marking task as FAILED. dag_id=download_cctv_data_to_postgresql, task_id=delete_data, execution_date=20231214T135926, start_date=20231214T135931, end_date=20231214T135931
[2023-12-14T13:59:31.561+0000] {warnings.py:109} WARNING - /home/***/.local/lib/python3.8/site-packages/***/utils/email.py:154: RemovedInAirflow3Warning: Fetching SMTP credentials from configuration variables will be deprecated in a future release. Please set credentials using a connection instead.
  send_mime_email(e_from=mail_from, e_to=recipients, mime_msg=msg, conn_id=conn_id, dryrun=dryrun)

[2023-12-14T13:59:31.567+0000] {configuration.py:1050} WARNING - section/key [smtp/smtp_user] not found in config
[2023-12-14T13:59:31.568+0000] {email.py:270} INFO - Email alerting: attempt 1
[2023-12-14T13:59:31.574+0000] {configuration.py:1050} WARNING - section/key [smtp/smtp_user] not found in config
[2023-12-14T13:59:31.574+0000] {email.py:270} INFO - Email alerting: attempt 1
[2023-12-14T13:59:31.576+0000] {taskinstance.py:2007} ERROR - Failed to send email to: ['christinelee1114@gmail.com']
Traceback (most recent call last):
  File "/home/airflow/.local/lib/python3.8/site-packages/airflow/models/taskinstance.py", line 1518, in _run_raw_task
    self._execute_task_with_callbacks(context, test_mode, session=session)
  File "/home/airflow/.local/lib/python3.8/site-packages/airflow/models/taskinstance.py", line 1681, in _execute_task_with_callbacks
    result = self._execute_task(context, task_orig)
  File "/home/airflow/.local/lib/python3.8/site-packages/airflow/models/taskinstance.py", line 1744, in _execute_task
    result = execute_callable(context=context, **execute_callable_kwargs)
  File "/home/airflow/.local/lib/python3.8/site-packages/airflow/providers/common/sql/operators/sql.py", line 280, in execute
    output = hook.run(
  File "/home/airflow/.local/lib/python3.8/site-packages/airflow/providers/common/sql/hooks/sql.py", line 385, in run
    with closing(self.get_conn()) as conn:
  File "/home/airflow/.local/lib/python3.8/site-packages/airflow/providers/postgres/hooks/postgres.py", line 155, in get_conn
    self.conn = psycopg2.connect(**conn_args)
  File "/home/airflow/.local/lib/python3.8/site-packages/psycopg2/__init__.py", line 122, in connect
    conn = _connect(dsn, connection_factory=connection_factory, **kwasync)
psycopg2.OperationalError: could not translate host name "host.docker.local" to address: Name or service not known


During handling of the above exception, another exception occurred:

Traceback (most recent call last):
  File "/home/airflow/.local/lib/python3.8/site-packages/airflow/models/taskinstance.py", line 2420, in email_alert
    send_email(task.email, subject, html_content)
  File "/home/airflow/.local/lib/python3.8/site-packages/airflow/utils/email.py", line 80, in send_email
    return backend(
  File "/home/airflow/.local/lib/python3.8/site-packages/airflow/utils/email.py", line 154, in send_email_smtp
    send_mime_email(e_from=mail_from, e_to=recipients, mime_msg=msg, conn_id=conn_id, dryrun=dryrun)
  File "/home/airflow/.local/lib/python3.8/site-packages/airflow/utils/email.py", line 272, in send_mime_email
    smtp_conn = _get_smtp_connection(smtp_host, smtp_port, smtp_timeout, smtp_ssl)
  File "/home/airflow/.local/lib/python3.8/site-packages/airflow/utils/email.py", line 316, in _get_smtp_connection
    return smtplib.SMTP(host=host, port=port, timeout=timeout)
  File "/usr/local/lib/python3.8/smtplib.py", line 255, in __init__
    (code, msg) = self.connect(host, port)
  File "/usr/local/lib/python3.8/smtplib.py", line 339, in connect
    self.sock = self._get_socket(host, port, self.timeout)
  File "/usr/local/lib/python3.8/smtplib.py", line 310, in _get_socket
    return socket.create_connection((host, port), timeout,
  File "/usr/local/lib/python3.8/socket.py", line 808, in create_connection
    raise err
  File "/usr/local/lib/python3.8/socket.py", line 796, in create_connection
    sock.connect(sa)
OSError: [Errno 99] Cannot assign requested address

During handling of the above exception, another exception occurred:

Traceback (most recent call last):
  File "/home/airflow/.local/lib/python3.8/site-packages/airflow/models/taskinstance.py", line 2005, in handle_failure
    self.email_alert(error, task)
  File "/home/airflow/.local/lib/python3.8/site-packages/airflow/models/taskinstance.py", line 2422, in email_alert
    send_email(task.email, subject, html_content_err)
  File "/home/airflow/.local/lib/python3.8/site-packages/airflow/utils/email.py", line 80, in send_email
    return backend(
  File "/home/airflow/.local/lib/python3.8/site-packages/airflow/utils/email.py", line 154, in send_email_smtp
    send_mime_email(e_from=mail_from, e_to=recipients, mime_msg=msg, conn_id=conn_id, dryrun=dryrun)
  File "/home/airflow/.local/lib/python3.8/site-packages/airflow/utils/email.py", line 272, in send_mime_email
    smtp_conn = _get_smtp_connection(smtp_host, smtp_port, smtp_timeout, smtp_ssl)
  File "/home/airflow/.local/lib/python3.8/site-packages/airflow/utils/email.py", line 316, in _get_smtp_connection
    return smtplib.SMTP(host=host, port=port, timeout=timeout)
  File "/usr/local/lib/python3.8/smtplib.py", line 255, in __init__
    (code, msg) = self.connect(host, port)
  File "/usr/local/lib/python3.8/smtplib.py", line 339, in connect
    self.sock = self._get_socket(host, port, self.timeout)
  File "/usr/local/lib/python3.8/smtplib.py", line 310, in _get_socket
    return socket.create_connection((host, port), timeout,
  File "/usr/local/lib/python3.8/socket.py", line 808, in create_connection
    raise err
  File "/usr/local/lib/python3.8/socket.py", line 796, in create_connection
    sock.connect(sa)
OSError: [Errno 99] Cannot assign requested address
[2023-12-14T13:59:31.590+0000] {standard_task_runner.py:104} ERROR - Failed to execute job 10 for task delete_data (could not translate host name "host.docker.local" to address: Name or service not known
; 193)
[2023-12-14T13:59:31.603+0000] {local_task_job_runner.py:228} INFO - Task exited with return code 1
[2023-12-14T13:59:31.622+0000] {taskinstance.py:2778} INFO - 0 downstream tasks scheduled from follow-on schedule check
