[2023-12-07T12:21:26.733+0000] {taskinstance.py:1159} INFO - Dependencies all met for dep_context=non-requeueable deps ti=<TaskInstance: crawl_and_store_to_mysql.store_csv_to_mysql scheduled__2023-01-01T00:00:00+00:00 [queued]>
[2023-12-07T12:21:26.741+0000] {taskinstance.py:1159} INFO - Dependencies all met for dep_context=requeueable deps ti=<TaskInstance: crawl_and_store_to_mysql.store_csv_to_mysql scheduled__2023-01-01T00:00:00+00:00 [queued]>
[2023-12-07T12:21:26.742+0000] {taskinstance.py:1361} INFO - Starting attempt 2 of 2
[2023-12-07T12:21:26.751+0000] {taskinstance.py:1382} INFO - Executing <Task(PythonOperator): store_csv_to_mysql> on 2023-01-01 00:00:00+00:00
[2023-12-07T12:21:26.800+0000] {standard_task_runner.py:57} INFO - Started process 37710 to run task
[2023-12-07T12:21:26.803+0000] {standard_task_runner.py:84} INFO - Running: ['***', 'tasks', 'run', 'crawl_and_store_to_mysql', 'store_csv_to_mysql', 'scheduled__2023-01-01T00:00:00+00:00', '--job-id', '45', '--raw', '--subdir', 'DAGS_FOLDER/download_cctv_data.py', '--cfg-path', '/tmp/tmp68yupt3g']
[2023-12-07T12:21:26.806+0000] {standard_task_runner.py:85} INFO - Job 45: Subtask store_csv_to_mysql
[2023-12-07T12:21:26.852+0000] {task_command.py:416} INFO - Running <TaskInstance: crawl_and_store_to_mysql.store_csv_to_mysql scheduled__2023-01-01T00:00:00+00:00 [running]> on host 7fd8dd875aa1
[2023-12-07T12:21:26.915+0000] {taskinstance.py:1662} INFO - Exporting env vars: AIRFLOW_CTX_DAG_OWNER='xin' AIRFLOW_CTX_DAG_ID='crawl_and_store_to_mysql' AIRFLOW_CTX_TASK_ID='store_csv_to_mysql' AIRFLOW_CTX_EXECUTION_DATE='2023-01-01T00:00:00+00:00' AIRFLOW_CTX_TRY_NUMBER='2' AIRFLOW_CTX_DAG_RUN_ID='scheduled__2023-01-01T00:00:00+00:00'
[2023-12-07T12:21:26.920+0000] {taskinstance.py:1937} ERROR - Task failed with exception
Traceback (most recent call last):
  File "/home/airflow/.local/lib/python3.8/site-packages/pymysql/connections.py", line 644, in connect
    sock = socket.create_connection(
  File "/usr/local/lib/python3.8/socket.py", line 808, in create_connection
    raise err
  File "/usr/local/lib/python3.8/socket.py", line 796, in create_connection
    sock.connect(sa)
OSError: [Errno 99] Cannot assign requested address

During handling of the above exception, another exception occurred:

Traceback (most recent call last):
  File "/home/airflow/.local/lib/python3.8/site-packages/airflow/operators/python.py", line 192, in execute
    return_value = self.execute_callable()
  File "/home/airflow/.local/lib/python3.8/site-packages/airflow/operators/python.py", line 209, in execute_callable
    return self.python_callable(*self.op_args, **self.op_kwargs)
  File "/opt/airflow/dags/download_cctv_data.py", line 129, in store_csv_to_mysql
    connection = pymysql.connect(
  File "/home/airflow/.local/lib/python3.8/site-packages/pymysql/connections.py", line 358, in __init__
    self.connect()
  File "/home/airflow/.local/lib/python3.8/site-packages/pymysql/connections.py", line 711, in connect
    raise exc
pymysql.err.OperationalError: (2003, "Can't connect to MySQL server on 'localhost' ([Errno 99] Cannot assign requested address)")
[2023-12-07T12:21:26.934+0000] {taskinstance.py:1400} INFO - Marking task as FAILED. dag_id=crawl_and_store_to_mysql, task_id=store_csv_to_mysql, execution_date=20230101T000000, start_date=20231207T122126, end_date=20231207T122126
[2023-12-07T12:21:26.949+0000] {standard_task_runner.py:104} ERROR - Failed to execute job 45 for task store_csv_to_mysql ((2003, "Can't connect to MySQL server on 'localhost' ([Errno 99] Cannot assign requested address)"); 37710)
[2023-12-07T12:21:26.978+0000] {local_task_job_runner.py:228} INFO - Task exited with return code 1
[2023-12-07T12:21:27.046+0000] {taskinstance.py:2778} INFO - 0 downstream tasks scheduled from follow-on schedule check
