[2023-12-18T19:45:03.292+0000] {taskinstance.py:1159} INFO - Dependencies all met for dep_context=non-requeueable deps ti=<TaskInstance: traffic_etl_storeToPostgres.create_cctv_data_table manual__2023-12-18T19:44:44.719232+00:00 [queued]>
[2023-12-18T19:45:03.301+0000] {taskinstance.py:1159} INFO - Dependencies all met for dep_context=requeueable deps ti=<TaskInstance: traffic_etl_storeToPostgres.create_cctv_data_table manual__2023-12-18T19:44:44.719232+00:00 [queued]>
[2023-12-18T19:45:03.301+0000] {taskinstance.py:1361} INFO - Starting attempt 1 of 1
[2023-12-18T19:45:03.313+0000] {taskinstance.py:1382} INFO - Executing <Task(PostgresOperator): create_cctv_data_table> on 2023-12-18 19:44:44.719232+00:00
[2023-12-18T19:45:03.321+0000] {standard_task_runner.py:57} INFO - Started process 1492 to run task
[2023-12-18T19:45:03.324+0000] {standard_task_runner.py:84} INFO - Running: ['***', 'tasks', 'run', 'traffic_etl_storeToPostgres', 'create_cctv_data_table', 'manual__2023-12-18T19:44:44.719232+00:00', '--job-id', '265', '--raw', '--subdir', 'DAGS_FOLDER/traffic_etl_storeToPostgres.py', '--cfg-path', '/tmp/tmp95gxl15q']
[2023-12-18T19:45:03.327+0000] {standard_task_runner.py:85} INFO - Job 265: Subtask create_cctv_data_table
[2023-12-18T19:45:03.369+0000] {task_command.py:416} INFO - Running <TaskInstance: traffic_etl_storeToPostgres.create_cctv_data_table manual__2023-12-18T19:44:44.719232+00:00 [running]> on host 8833c94e6466
[2023-12-18T19:45:03.435+0000] {taskinstance.py:1662} INFO - Exporting env vars: AIRFLOW_CTX_DAG_EMAIL='christinelee1114@gmail.com' AIRFLOW_CTX_DAG_OWNER='xin' AIRFLOW_CTX_DAG_ID='traffic_etl_storeToPostgres' AIRFLOW_CTX_TASK_ID='create_cctv_data_table' AIRFLOW_CTX_EXECUTION_DATE='2023-12-18T19:44:44.719232+00:00' AIRFLOW_CTX_TRY_NUMBER='1' AIRFLOW_CTX_DAG_RUN_ID='manual__2023-12-18T19:44:44.719232+00:00'
[2023-12-18T19:45:03.437+0000] {sql.py:274} INFO - Executing: 

            CREATE TABLE traffic (
                id SERIAL PRIMARY KEY,
                年 INTEGER,
                月 INTEGER,
                日 INTEGER,
                日期 DATE,
                受傷人數 INTEGER,
                市區鄉鎮 VARCHAR(50),
                是否飲酒 VARCHAR(3),
                時間 INTEGER,
                死亡人數 INTEGER,
                當事者順位 INTEGER,
                白天or夜晚 VARCHAR(10),
                經度 DOUBLE PRECISION,
                緯度 DOUBLE PRECISION,
                縣市 VARCHAR(50),
                道路類型 VARCHAR(20)
            );

            
[2023-12-18T19:45:03.447+0000] {base.py:73} INFO - Using connection ID 'postgres_conn' for task execution.
[2023-12-18T19:45:03.457+0000] {base.py:73} INFO - Using connection ID 'postgres_conn' for task execution.
[2023-12-18T19:45:03.498+0000] {sql.py:418} INFO - Running statement: 

            CREATE TABLE traffic (
                id SERIAL PRIMARY KEY,
                年 INTEGER,
                月 INTEGER,
                日 INTEGER,
                日期 DATE,
                受傷人數 INTEGER,
                市區鄉鎮 VARCHAR(50),
                是否飲酒 VARCHAR(3),
                時間 INTEGER,
                死亡人數 INTEGER,
                當事者順位 INTEGER,
                白天or夜晚 VARCHAR(10),
                經度 DOUBLE PRECISION,
                緯度 DOUBLE PRECISION,
                縣市 VARCHAR(50),
                道路類型 VARCHAR(20)
            );

            , parameters: None
[2023-12-18T19:45:03.507+0000] {taskinstance.py:1937} ERROR - Task failed with exception
Traceback (most recent call last):
  File "/home/airflow/.local/lib/python3.8/site-packages/airflow/providers/common/sql/operators/sql.py", line 280, in execute
    output = hook.run(
  File "/home/airflow/.local/lib/python3.8/site-packages/airflow/providers/common/sql/hooks/sql.py", line 392, in run
    self._run_command(cur, sql_statement, parameters)
  File "/home/airflow/.local/lib/python3.8/site-packages/airflow/providers/common/sql/hooks/sql.py", line 423, in _run_command
    cur.execute(sql_statement)
psycopg2.errors.DuplicateTable: relation "traffic" already exists

[2023-12-18T19:45:03.516+0000] {taskinstance.py:1400} INFO - Marking task as FAILED. dag_id=traffic_etl_storeToPostgres, task_id=create_cctv_data_table, execution_date=20231218T194444, start_date=20231218T194503, end_date=20231218T194503
[2023-12-18T19:45:03.528+0000] {standard_task_runner.py:104} ERROR - Failed to execute job 265 for task create_cctv_data_table (relation "traffic" already exists
; 1492)
[2023-12-18T19:45:03.576+0000] {local_task_job_runner.py:228} INFO - Task exited with return code 1
[2023-12-18T19:45:03.598+0000] {taskinstance.py:2778} INFO - 0 downstream tasks scheduled from follow-on schedule check
